<robot name="simple_robot">
  <link name="base_link">
    <visual>
      <geometry>
        <box size="0.5 0.3 0.1"/>
      </geometry>
      <material name="blue">
        <color rgba="0 0 0.8 1"/>
      </material>
    </visual>
    <collision>
      <geometry>
        <box size="0.5 0.3 0.1"/>
      </geometry>
    </collision>
    <inertial>
      <mass value="1.0"/>
      <inertia ixx="0.0166667" ixy="0" ixz="0" iyy="0.0166667" iyz="0" izz="0.0166667"/>
    </inertial>
  </link>

  <gazebo>
    <plugin name="diff_drive" filename="libgazebo_ros_diff_drive.so">
      <left_joint>left_wheel_joint</left_joint>
      <right_joint>right_wheel_joint</right_joint>
      <wheel_separation>0.3</wheel_separation>
      <wheel_diameter>0.1</wheel_diameter>
      <max_wheel_torque>20</max_wheel_torque>
      <max_wheel_acceleration>1.0</max_wheel_acceleration>
      <odometry_frame>odom</odometry_frame>
      <robot_base_frame>base_link</robot_base_frame>
      <publish_odom>true</publish_odom>
      <publish_wheel_tf>true</publish_wheel_tf>
      <publish_wheel_joint_state>true</publish_wheel_joint_state>
    </plugin>
  </gazebo>

  <link name="left_wheel">
    <visual>
      <geometry>
        <cylinder radius="0.05" length="0.04"/>
      </geometry>
      <material name="black">
        <color rgba="0 0 0 1"/>
      </material>
    </visual>
    <collision>
      <geometry>
        <cylinder radius="0.05" length="0.04"/>
      </geometry>
    </collision>
    <inertial>
      <mass value="0.1"/>
      <inertia ixx="0.000041667" ixy="0" ixz="0" iyy="0.000041667" iyz="0" izz="0.000075"/>
    </inertial>
  </link>

  <link name="right_wheel">
    <visual>
      <geometry>
        <cylinder radius="0.05" length="0.04"/>
      </geometry>
      <material name="black">
        <color rgba="0 0 0 1"/>
      </material>
    </visual>
    <collision>
      <geometry>
        <cylinder radius="0.05" length="0.04"/>
      </geometry>
    </collision>
    <inertial>
      <mass value="0.1"/>
      <inertia ixx="0.000041667" ixy="0" ixz="0" iyy="0.000041667" iyz="0" izz="0.000075"/>
    </inertial>
  </link>

  <joint name="left_wheel_joint" type="continuous">
    <parent link="base_link"/>
    <child link="left_wheel"/>
    <origin xyz="-0.1 0.15 0" rpy="-1.5707 0 0"/>
    <axis xyz="0 0 1"/>
  </joint>

  <joint name="right_wheel_joint" type="continuous">
    <parent link="base_link"/>
    <child link="right_wheel"/>
    <origin xyz="-0.1 -0.15 0" rpy="-1.5707 0 0"/>
    <axis xyz="0 0 1"/>
  </joint>
</robot>
